[2023-12-07T13:50:57.376+0000] {taskinstance.py:1159} INFO - Dependencies all met for dep_context=non-requeueable deps ti=<TaskInstance: good_morning_1.get_cur_rate scheduled__2023-12-07T12:30:00+00:00 [queued]>
[2023-12-07T13:50:57.396+0000] {taskinstance.py:1159} INFO - Dependencies all met for dep_context=requeueable deps ti=<TaskInstance: good_morning_1.get_cur_rate scheduled__2023-12-07T12:30:00+00:00 [queued]>
[2023-12-07T13:50:57.397+0000] {taskinstance.py:1361} INFO - Starting attempt 1 of 2
[2023-12-07T13:50:57.426+0000] {taskinstance.py:1382} INFO - Executing <Task(DockerOperator): get_cur_rate> on 2023-12-07 12:30:00+00:00
[2023-12-07T13:50:57.438+0000] {standard_task_runner.py:57} INFO - Started process 66 to run task
[2023-12-07T13:50:57.444+0000] {standard_task_runner.py:84} INFO - Running: ['***', 'tasks', 'run', 'good_morning_1', 'get_cur_rate', 'scheduled__2023-12-07T12:30:00+00:00', '--job-id', '79', '--raw', '--subdir', 'DAGS_FOLDER/good_mornig.py', '--cfg-path', '/tmp/tmpbum320ke']
[2023-12-07T13:50:57.450+0000] {standard_task_runner.py:85} INFO - Job 79: Subtask get_cur_rate
[2023-12-07T13:50:57.542+0000] {task_command.py:416} INFO - Running <TaskInstance: good_morning_1.get_cur_rate scheduled__2023-12-07T12:30:00+00:00 [running]> on host 02313c0b90f9
[2023-12-07T13:50:57.702+0000] {taskinstance.py:1662} INFO - Exporting env vars: AIRFLOW_CTX_DAG_OWNER='mdv' AIRFLOW_CTX_DAG_ID='good_morning_1' AIRFLOW_CTX_TASK_ID='get_cur_rate' AIRFLOW_CTX_EXECUTION_DATE='2023-12-07T12:30:00+00:00' AIRFLOW_CTX_TRY_NUMBER='1' AIRFLOW_CTX_DAG_RUN_ID='scheduled__2023-12-07T12:30:00+00:00'
[2023-12-07T13:50:57.763+0000] {docker.py:343} INFO - Starting docker container from image masalskii/ex-rate
[2023-12-07T13:50:57.781+0000] {docker.py:351} WARNING - Using remote engine or docker-in-docker and mounting temporary volume from host is not supported. Falling back to `mount_tmp_dir=False` mode. You can set `mount_tmp_dir` parameter to False to disable mounting and remove the warning
[2023-12-07T13:51:00.710+0000] {docker.py:413} INFO - ['exchangerate.py', 'l', 'BTC', 'RUB']
[2023-12-07T13:51:01.143+0000] {docker.py:413} INFO - {'success': True, 'terms': 'https://currencylayer.com/terms', 'privacy': 'https://currencylayer.com/privacy', 'timestamp': 1701957004, 'source': 'BTC', 'quotes': {'BTCRUB': 4014030.247451}}
[2023-12-07T13:51:01.147+0000] {docker.py:413} INFO - Traceback (most recent call last):
  File "/app/exchangerate.py", line 266, in <module>
[2023-12-07T13:51:01.148+0000] {docker.py:413} INFO - main()
  File "/app/exchangerate.py", line 35, in main
[2023-12-07T13:51:01.149+0000] {docker.py:413} INFO - get_latest_rate(argv[2], argv[3])
  File "/app/exchangerate.py", line 83, in get_latest_rate
    insert_data(data)
  File "/app/exchangerate.py", line 121, in insert_data
[2023-12-07T13:51:01.150+0000] {docker.py:413} INFO - connection = ps2.connect(
  File "/usr/local/lib/python3.10/site-packages/psycopg2/__init__.py", line 122, in connect
[2023-12-07T13:51:01.151+0000] {docker.py:413} INFO - conn = _connect(dsn, connection_factory=connection_factory, **kwasync)
psycopg2.OperationalError: connection to server at "host.docker.internal" (192.168.65.2), port 5434 failed: Connection refused
	Is the server running on that host and accepting TCP/IP connections?
[2023-12-07T13:51:01.501+0000] {taskinstance.py:1937} ERROR - Task failed with exception
Traceback (most recent call last):
  File "/home/airflow/.local/lib/python3.8/site-packages/docker/api/client.py", line 268, in _raise_for_status
    response.raise_for_status()
  File "/home/airflow/.local/lib/python3.8/site-packages/requests/models.py", line 1021, in raise_for_status
    raise HTTPError(http_error_msg, response=self)
requests.exceptions.HTTPError: 400 Client Error: Bad Request for url: http+docker://localhost/v1.43/containers/create?name=task____comand_hello

The above exception was the direct cause of the following exception:

Traceback (most recent call last):
  File "/home/airflow/.local/lib/python3.8/site-packages/airflow/providers/docker/operators/docker.py", line 348, in _run_image
    return self._run_image_with_mounts([*self.mounts, tmp_mount], add_tmp_variable=True)
  File "/home/airflow/.local/lib/python3.8/site-packages/airflow/providers/docker/operators/docker.py", line 375, in _run_image_with_mounts
    self.container = self.cli.create_container(
  File "/home/airflow/.local/lib/python3.8/site-packages/docker/api/container.py", line 431, in create_container
    return self.create_container_from_config(config, name, platform)
  File "/home/airflow/.local/lib/python3.8/site-packages/docker/api/container.py", line 448, in create_container_from_config
    return self._result(res, True)
  File "/home/airflow/.local/lib/python3.8/site-packages/docker/api/client.py", line 274, in _result
    self._raise_for_status(response)
  File "/home/airflow/.local/lib/python3.8/site-packages/docker/api/client.py", line 270, in _raise_for_status
    raise create_api_error_from_http_exception(e) from e
  File "/home/airflow/.local/lib/python3.8/site-packages/docker/errors.py", line 39, in create_api_error_from_http_exception
    raise cls(e, response=response, explanation=explanation) from e
docker.errors.APIError: 400 Client Error for http+docker://localhost/v1.43/containers/create?name=task____comand_hello: Bad Request ("invalid mount config for type "bind": bind source path does not exist: /tmp/airflowtmp24yfo2_k")

During handling of the above exception, another exception occurred:

Traceback (most recent call last):
  File "/home/airflow/.local/lib/python3.8/site-packages/airflow/providers/docker/operators/docker.py", line 486, in execute
    return self._run_image()
  File "/home/airflow/.local/lib/python3.8/site-packages/airflow/providers/docker/operators/docker.py", line 357, in _run_image
    return self._run_image_with_mounts(self.mounts, add_tmp_variable=False)
  File "/home/airflow/.local/lib/python3.8/site-packages/airflow/providers/docker/operators/docker.py", line 421, in _run_image_with_mounts
    raise DockerContainerFailedException(f"Docker container failed: {result!r}", logs=log_lines)
airflow.providers.docker.exceptions.DockerContainerFailedException: Docker container failed: {'StatusCode': 1}
[2023-12-07T13:51:01.511+0000] {taskinstance.py:1400} INFO - Marking task as UP_FOR_RETRY. dag_id=good_morning_1, task_id=get_cur_rate, execution_date=20231207T123000, start_date=20231207T135057, end_date=20231207T135101
[2023-12-07T13:51:01.547+0000] {standard_task_runner.py:104} ERROR - Failed to execute job 79 for task get_cur_rate (Docker container failed: {'StatusCode': 1}; 66)
[2023-12-07T13:51:01.582+0000] {local_task_job_runner.py:228} INFO - Task exited with return code 1
[2023-12-07T13:51:01.659+0000] {taskinstance.py:2778} INFO - 0 downstream tasks scheduled from follow-on schedule check
