[2023-12-07T13:55:14.726+0000] {taskinstance.py:1159} INFO - Dependencies all met for dep_context=non-requeueable deps ti=<TaskInstance: good_morning_1.get_cur_rate scheduled__2023-12-07T13:40:00+00:00 [queued]>
[2023-12-07T13:55:14.742+0000] {taskinstance.py:1159} INFO - Dependencies all met for dep_context=requeueable deps ti=<TaskInstance: good_morning_1.get_cur_rate scheduled__2023-12-07T13:40:00+00:00 [queued]>
[2023-12-07T13:55:14.743+0000] {taskinstance.py:1361} INFO - Starting attempt 2 of 2
[2023-12-07T13:55:14.765+0000] {taskinstance.py:1382} INFO - Executing <Task(DockerOperator): get_cur_rate> on 2023-12-07 13:40:00+00:00
[2023-12-07T13:55:14.776+0000] {standard_task_runner.py:57} INFO - Started process 60 to run task
[2023-12-07T13:55:14.781+0000] {standard_task_runner.py:84} INFO - Running: ['***', 'tasks', 'run', 'good_morning_1', 'get_cur_rate', 'scheduled__2023-12-07T13:40:00+00:00', '--job-id', '85', '--raw', '--subdir', 'DAGS_FOLDER/good_mornig.py', '--cfg-path', '/tmp/tmpsz412h0o']
[2023-12-07T13:55:14.786+0000] {standard_task_runner.py:85} INFO - Job 85: Subtask get_cur_rate
[2023-12-07T13:55:14.869+0000] {task_command.py:416} INFO - Running <TaskInstance: good_morning_1.get_cur_rate scheduled__2023-12-07T13:40:00+00:00 [running]> on host 4b634edee93d
[2023-12-07T13:55:15.032+0000] {taskinstance.py:1662} INFO - Exporting env vars: AIRFLOW_CTX_DAG_OWNER='mdv' AIRFLOW_CTX_DAG_ID='good_morning_1' AIRFLOW_CTX_TASK_ID='get_cur_rate' AIRFLOW_CTX_EXECUTION_DATE='2023-12-07T13:40:00+00:00' AIRFLOW_CTX_TRY_NUMBER='2' AIRFLOW_CTX_DAG_RUN_ID='scheduled__2023-12-07T13:40:00+00:00'
[2023-12-07T13:55:15.097+0000] {docker.py:343} INFO - Starting docker container from image masalskii/ex-rate
[2023-12-07T13:55:15.142+0000] {docker.py:351} WARNING - Using remote engine or docker-in-docker and mounting temporary volume from host is not supported. Falling back to `mount_tmp_dir=False` mode. You can set `mount_tmp_dir` parameter to False to disable mounting and remove the warning
[2023-12-07T13:55:15.196+0000] {taskinstance.py:1937} ERROR - Task failed with exception
Traceback (most recent call last):
  File "/home/airflow/.local/lib/python3.8/site-packages/docker/api/client.py", line 268, in _raise_for_status
    response.raise_for_status()
  File "/home/airflow/.local/lib/python3.8/site-packages/requests/models.py", line 1021, in raise_for_status
    raise HTTPError(http_error_msg, response=self)
requests.exceptions.HTTPError: 400 Client Error: Bad Request for url: http+docker://localhost/v1.43/containers/create?name=task____comand_hello

The above exception was the direct cause of the following exception:

Traceback (most recent call last):
  File "/home/airflow/.local/lib/python3.8/site-packages/airflow/providers/docker/operators/docker.py", line 348, in _run_image
    return self._run_image_with_mounts([*self.mounts, tmp_mount], add_tmp_variable=True)
  File "/home/airflow/.local/lib/python3.8/site-packages/airflow/providers/docker/operators/docker.py", line 375, in _run_image_with_mounts
    self.container = self.cli.create_container(
  File "/home/airflow/.local/lib/python3.8/site-packages/docker/api/container.py", line 431, in create_container
    return self.create_container_from_config(config, name, platform)
  File "/home/airflow/.local/lib/python3.8/site-packages/docker/api/container.py", line 448, in create_container_from_config
    return self._result(res, True)
  File "/home/airflow/.local/lib/python3.8/site-packages/docker/api/client.py", line 274, in _result
    self._raise_for_status(response)
  File "/home/airflow/.local/lib/python3.8/site-packages/docker/api/client.py", line 270, in _raise_for_status
    raise create_api_error_from_http_exception(e) from e
  File "/home/airflow/.local/lib/python3.8/site-packages/docker/errors.py", line 39, in create_api_error_from_http_exception
    raise cls(e, response=response, explanation=explanation) from e
docker.errors.APIError: 400 Client Error for http+docker://localhost/v1.43/containers/create?name=task____comand_hello: Bad Request ("invalid mount config for type "bind": bind source path does not exist: /tmp/airflowtmpftd3wndc")

During handling of the above exception, another exception occurred:

Traceback (most recent call last):
  File "/home/airflow/.local/lib/python3.8/site-packages/docker/api/client.py", line 268, in _raise_for_status
    response.raise_for_status()
  File "/home/airflow/.local/lib/python3.8/site-packages/requests/models.py", line 1021, in raise_for_status
    raise HTTPError(http_error_msg, response=self)
requests.exceptions.HTTPError: 409 Client Error: Conflict for url: http+docker://localhost/v1.43/containers/create?name=task____comand_hello

The above exception was the direct cause of the following exception:

Traceback (most recent call last):
  File "/home/airflow/.local/lib/python3.8/site-packages/airflow/providers/docker/operators/docker.py", line 486, in execute
    return self._run_image()
  File "/home/airflow/.local/lib/python3.8/site-packages/airflow/providers/docker/operators/docker.py", line 357, in _run_image
    return self._run_image_with_mounts(self.mounts, add_tmp_variable=False)
  File "/home/airflow/.local/lib/python3.8/site-packages/airflow/providers/docker/operators/docker.py", line 375, in _run_image_with_mounts
    self.container = self.cli.create_container(
  File "/home/airflow/.local/lib/python3.8/site-packages/docker/api/container.py", line 431, in create_container
    return self.create_container_from_config(config, name, platform)
  File "/home/airflow/.local/lib/python3.8/site-packages/docker/api/container.py", line 448, in create_container_from_config
    return self._result(res, True)
  File "/home/airflow/.local/lib/python3.8/site-packages/docker/api/client.py", line 274, in _result
    self._raise_for_status(response)
  File "/home/airflow/.local/lib/python3.8/site-packages/docker/api/client.py", line 270, in _raise_for_status
    raise create_api_error_from_http_exception(e) from e
  File "/home/airflow/.local/lib/python3.8/site-packages/docker/errors.py", line 39, in create_api_error_from_http_exception
    raise cls(e, response=response, explanation=explanation) from e
docker.errors.APIError: 409 Client Error for http+docker://localhost/v1.43/containers/create?name=task____comand_hello: Conflict ("Conflict. The container name "/task____comand_hello" is already in use by container "df38f76fc37f58cca7385b0f1c48cd9de206fef48b80c452a4ad7eae35d0a898". You have to remove (or rename) that container to be able to reuse that name.")
[2023-12-07T13:55:15.227+0000] {taskinstance.py:1400} INFO - Marking task as FAILED. dag_id=good_morning_1, task_id=get_cur_rate, execution_date=20231207T134000, start_date=20231207T135514, end_date=20231207T135515
[2023-12-07T13:55:15.288+0000] {standard_task_runner.py:104} ERROR - Failed to execute job 85 for task get_cur_rate (409 Client Error for http+docker://localhost/v1.43/containers/create?name=task____comand_hello: Conflict ("Conflict. The container name "/task____comand_hello" is already in use by container "df38f76fc37f58cca7385b0f1c48cd9de206fef48b80c452a4ad7eae35d0a898". You have to remove (or rename) that container to be able to reuse that name."); 60)
[2023-12-07T13:55:15.342+0000] {local_task_job_runner.py:228} INFO - Task exited with return code 1
[2023-12-07T13:55:15.404+0000] {taskinstance.py:2778} INFO - 0 downstream tasks scheduled from follow-on schedule check
